Traceback (most recent call last):
  File "/Users/alexbel/Desktop/Проекты/AI Fitness Coach/.venv/lib/python3.12/site-packages/django/db/backends/base/base.py", line 275, in ensure_connection
    self.connect()
  File "/Users/alexbel/Desktop/Проекты/AI Fitness Coach/.venv/lib/python3.12/site-packages/django/utils/asyncio.py", line 26, in inner
    return func(*args, **kwargs)
           ^^^^^^^^^^^^^^^^^^^^^
  File "/Users/alexbel/Desktop/Проекты/AI Fitness Coach/.venv/lib/python3.12/site-packages/django/db/backends/base/base.py", line 256, in connect
    self.connection = self.get_new_connection(conn_params)
                      ^^^^^^^^^^^^^^^^^^^^^^^^^^^^^^^^^^^^
  File "/Users/alexbel/Desktop/Проекты/AI Fitness Coach/.venv/lib/python3.12/site-packages/django/utils/asyncio.py", line 26, in inner
    return func(*args, **kwargs)
           ^^^^^^^^^^^^^^^^^^^^^
  File "/Users/alexbel/Desktop/Проекты/AI Fitness Coach/.venv/lib/python3.12/site-packages/django/db/backends/postgresql/base.py", line 277, in get_new_connection
    connection = self.Database.connect(**conn_params)
                 ^^^^^^^^^^^^^^^^^^^^^^^^^^^^^^^^^^^^
  File "/Users/alexbel/Desktop/Проекты/AI Fitness Coach/.venv/lib/python3.12/site-packages/psycopg2/__init__.py", line 122, in connect
    conn = _connect(dsn, connection_factory=connection_factory, **kwasync)
           ^^^^^^^^^^^^^^^^^^^^^^^^^^^^^^^^^^^^^^^^^^^^^^^^^^^^^^^^^^^^^^^
psycopg2.OperationalError: подключиться к серверу "localhost" (::1), порту 5432 не удалось: затребовано подключение через SSL, но сервер не поддерживает SSL


The above exception was the direct cause of the following exception:

Traceback (most recent call last):
  File "/Users/alexbel/Desktop/Проекты/AI Fitness Coach/manage.py", line 22, in <module>
    main()
  File "/Users/alexbel/Desktop/Проекты/AI Fitness Coach/manage.py", line 18, in main
    execute_from_command_line(sys.argv)
  File "/Users/alexbel/Desktop/Проекты/AI Fitness Coach/.venv/lib/python3.12/site-packages/django/core/management/__init__.py", line 442, in execute_from_command_line
    utility.execute()
  File "/Users/alexbel/Desktop/Проекты/AI Fitness Coach/.venv/lib/python3.12/site-packages/django/core/management/__init__.py", line 436, in execute
    self.fetch_command(subcommand).run_from_argv(self.argv)
  File "/Users/alexbel/Desktop/Проекты/AI Fitness Coach/.venv/lib/python3.12/site-packages/django/core/management/base.py", line 413, in run_from_argv
    self.execute(*args, **cmd_options)
  File "/Users/alexbel/Desktop/Проекты/AI Fitness Coach/.venv/lib/python3.12/site-packages/django/core/management/base.py", line 459, in execute
    output = self.handle(*args, **options)
             ^^^^^^^^^^^^^^^^^^^^^^^^^^^^^
  File "/Users/alexbel/Desktop/Проекты/AI Fitness Coach/.venv/lib/python3.12/site-packages/django/core/management/commands/showmigrations.py", line 66, in handle
    return self.show_list(connection, options["app_label"])
           ^^^^^^^^^^^^^^^^^^^^^^^^^^^^^^^^^^^^^^^^^^^^^^^^
  File "/Users/alexbel/Desktop/Проекты/AI Fitness Coach/.venv/lib/python3.12/site-packages/django/core/management/commands/showmigrations.py", line 85, in show_list
    loader = MigrationLoader(connection, ignore_no_migrations=True)
             ^^^^^^^^^^^^^^^^^^^^^^^^^^^^^^^^^^^^^^^^^^^^^^^^^^^^^^
  File "/Users/alexbel/Desktop/Проекты/AI Fitness Coach/.venv/lib/python3.12/site-packages/django/db/migrations/loader.py", line 58, in __init__
    self.build_graph()
  File "/Users/alexbel/Desktop/Проекты/AI Fitness Coach/.venv/lib/python3.12/site-packages/django/db/migrations/loader.py", line 235, in build_graph
    self.applied_migrations = recorder.applied_migrations()
                              ^^^^^^^^^^^^^^^^^^^^^^^^^^^^^
  File "/Users/alexbel/Desktop/Проекты/AI Fitness Coach/.venv/lib/python3.12/site-packages/django/db/migrations/recorder.py", line 89, in applied_migrations
    if self.has_table():
       ^^^^^^^^^^^^^^^^
  File "/Users/alexbel/Desktop/Проекты/AI Fitness Coach/.venv/lib/python3.12/site-packages/django/db/migrations/recorder.py", line 63, in has_table
    with self.connection.cursor() as cursor:
         ^^^^^^^^^^^^^^^^^^^^^^^^
  File "/Users/alexbel/Desktop/Проекты/AI Fitness Coach/.venv/lib/python3.12/site-packages/django/utils/asyncio.py", line 26, in inner
    return func(*args, **kwargs)
           ^^^^^^^^^^^^^^^^^^^^^
  File "/Users/alexbel/Desktop/Проекты/AI Fitness Coach/.venv/lib/python3.12/site-packages/django/db/backends/base/base.py", line 316, in cursor
    return self._cursor()
           ^^^^^^^^^^^^^^
  File "/Users/alexbel/Desktop/Проекты/AI Fitness Coach/.venv/lib/python3.12/site-packages/django/db/backends/base/base.py", line 292, in _cursor
    self.ensure_connection()
  File "/Users/alexbel/Desktop/Проекты/AI Fitness Coach/.venv/lib/python3.12/site-packages/django/utils/asyncio.py", line 26, in inner
    return func(*args, **kwargs)
           ^^^^^^^^^^^^^^^^^^^^^
  File "/Users/alexbel/Desktop/Проекты/AI Fitness Coach/.venv/lib/python3.12/site-packages/django/db/backends/base/base.py", line 274, in ensure_connection
    with self.wrap_database_errors:
  File "/Users/alexbel/Desktop/Проекты/AI Fitness Coach/.venv/lib/python3.12/site-packages/django/db/utils.py", line 91, in __exit__
    raise dj_exc_value.with_traceback(traceback) from exc_value
  File "/Users/alexbel/Desktop/Проекты/AI Fitness Coach/.venv/lib/python3.12/site-packages/django/db/backends/base/base.py", line 275, in ensure_connection
    self.connect()
  File "/Users/alexbel/Desktop/Проекты/AI Fitness Coach/.venv/lib/python3.12/site-packages/django/utils/asyncio.py", line 26, in inner
    return func(*args, **kwargs)
           ^^^^^^^^^^^^^^^^^^^^^
  File "/Users/alexbel/Desktop/Проекты/AI Fitness Coach/.venv/lib/python3.12/site-packages/django/db/backends/base/base.py", line 256, in connect
    self.connection = self.get_new_connection(conn_params)
                      ^^^^^^^^^^^^^^^^^^^^^^^^^^^^^^^^^^^^
  File "/Users/alexbel/Desktop/Проекты/AI Fitness Coach/.venv/lib/python3.12/site-packages/django/utils/asyncio.py", line 26, in inner
    return func(*args, **kwargs)
           ^^^^^^^^^^^^^^^^^^^^^
  File "/Users/alexbel/Desktop/Проекты/AI Fitness Coach/.venv/lib/python3.12/site-packages/django/db/backends/postgresql/base.py", line 277, in get_new_connection
    connection = self.Database.connect(**conn_params)
                 ^^^^^^^^^^^^^^^^^^^^^^^^^^^^^^^^^^^^
  File "/Users/alexbel/Desktop/Проекты/AI Fitness Coach/.venv/lib/python3.12/site-packages/psycopg2/__init__.py", line 122, in connect
    conn = _connect(dsn, connection_factory=connection_factory, **kwasync)
           ^^^^^^^^^^^^^^^^^^^^^^^^^^^^^^^^^^^^^^^^^^^^^^^^^^^^^^^^^^^^^^^
django.db.utils.OperationalError: подключиться к серверу "localhost" (::1), порту 5432 не удалось: затребовано подключение через SSL, но сервер не поддерживает SSL

